Traceback (most recent call last):
  File "/usr/local/lib/python3.12/dist-packages/jupyter_core/utils/__init__.py", line 154, in wrapped
    asyncio.get_running_loop()
RuntimeError: no running event loop

During handling of the above exception, another exception occurred:

Traceback (most recent call last):
  File "/usr/local/lib/python3.12/dist-packages/jupyter_cache/executors/utils.py", line 58, in single_nb_execution
    executenb(
  File "/usr/local/lib/python3.12/dist-packages/nbclient/client.py", line 1319, in execute
    return NotebookClient(nb=nb, resources=resources, km=km, **kwargs).execute()
           ^^^^^^^^^^^^^^^^^^^^^^^^^^^^^^^^^^^^^^^^^^^^^^^^^^^^^^^^^^^^^^^^^^^^^
  File "/usr/local/lib/python3.12/dist-packages/jupyter_core/utils/__init__.py", line 158, in wrapped
    return loop.run_until_complete(inner)
           ^^^^^^^^^^^^^^^^^^^^^^^^^^^^^^
  File "/usr/lib/python3.12/asyncio/base_events.py", line 691, in run_until_complete
    return future.result()
           ^^^^^^^^^^^^^^^
  File "/usr/local/lib/python3.12/dist-packages/nbclient/client.py", line 709, in async_execute
    await self.async_execute_cell(
  File "/usr/local/lib/python3.12/dist-packages/nbclient/client.py", line 1062, in async_execute_cell
    await self._check_raise_for_error(cell, cell_index, exec_reply)
  File "/usr/local/lib/python3.12/dist-packages/nbclient/client.py", line 918, in _check_raise_for_error
    raise CellExecutionError.from_cell_and_msg(cell, exec_reply_content)
nbclient.exceptions.CellExecutionError: An error occurred while executing the following cell:
------------------
# Gabungkan dalam pipeline (urutan penting!)
adasyn = ADASYN(random_state=42)
ros = RandomOverSampler(sampling_strategy=sampling_strategy_step1, random_state=42)
pipeline = Pipeline([('ros', ros), ('adasyn', adasyn)])

# Jalankan proses resampling
X_resampled, y_resampled = pipeline.fit_resample(X, y)
------------------


[0;31m---------------------------------------------------------------------------[0m
[0;31mNameError[0m                                 Traceback (most recent call last)
[0;32m/tmp/ipython-input-1247001434.py[0m in [0;36m<cell line: 0>[0;34m()[0m
[1;32m      1[0m [0;31m# Gabungkan dalam pipeline (urutan penting!)[0m[0;34m[0m[0;34m[0m[0m
[0;32m----> 2[0;31m [0madasyn[0m [0;34m=[0m [0mADASYN[0m[0;34m([0m[0mrandom_state[0m[0;34m=[0m[0;36m42[0m[0;34m)[0m[0;34m[0m[0;34m[0m[0m
[0m[1;32m      3[0m [0mros[0m [0;34m=[0m [0mRandomOverSampler[0m[0;34m([0m[0msampling_strategy[0m[0;34m=[0m[0msampling_strategy_step1[0m[0;34m,[0m [0mrandom_state[0m[0;34m=[0m[0;36m42[0m[0;34m)[0m[0;34m[0m[0;34m[0m[0m
[1;32m      4[0m [0mpipeline[0m [0;34m=[0m [0mPipeline[0m[0;34m([0m[0;34m[[0m[0;34m([0m[0;34m'ros'[0m[0;34m,[0m [0mros[0m[0;34m)[0m[0;34m,[0m [0;34m([0m[0;34m'adasyn'[0m[0;34m,[0m [0madasyn[0m[0;34m)[0m[0;34m][0m[0;34m)[0m[0;34m[0m[0;34m[0m[0m
[1;32m      5[0m [0;34m[0m[0m

[0;31mNameError[0m: name 'ADASYN' is not defined

