Traceback (most recent call last):
  File "/usr/local/lib/python3.12/dist-packages/jupyter_core/utils/__init__.py", line 154, in wrapped
    asyncio.get_running_loop()
RuntimeError: no running event loop

During handling of the above exception, another exception occurred:

Traceback (most recent call last):
  File "/usr/local/lib/python3.12/dist-packages/jupyter_cache/executors/utils.py", line 58, in single_nb_execution
    executenb(
  File "/usr/local/lib/python3.12/dist-packages/nbclient/client.py", line 1319, in execute
    return NotebookClient(nb=nb, resources=resources, km=km, **kwargs).execute()
           ^^^^^^^^^^^^^^^^^^^^^^^^^^^^^^^^^^^^^^^^^^^^^^^^^^^^^^^^^^^^^^^^^^^^^
  File "/usr/local/lib/python3.12/dist-packages/jupyter_core/utils/__init__.py", line 158, in wrapped
    return loop.run_until_complete(inner)
           ^^^^^^^^^^^^^^^^^^^^^^^^^^^^^^
  File "/usr/lib/python3.12/asyncio/base_events.py", line 691, in run_until_complete
    return future.result()
           ^^^^^^^^^^^^^^^
  File "/usr/local/lib/python3.12/dist-packages/nbclient/client.py", line 709, in async_execute
    await self.async_execute_cell(
  File "/usr/local/lib/python3.12/dist-packages/nbclient/client.py", line 1062, in async_execute_cell
    await self._check_raise_for_error(cell, cell_index, exec_reply)
  File "/usr/local/lib/python3.12/dist-packages/nbclient/client.py", line 918, in _check_raise_for_error
    raise CellExecutionError.from_cell_and_msg(cell, exec_reply_content)
nbclient.exceptions.CellExecutionError: An error occurred while executing the following cell:
------------------
# LANGKAH 2: ANALISIS & PERSIAPAN DATA
print("\n--- LANGKAH 2: Menganalisis dan Mempersiapkan Data ---")
feature_columns = ['mcg', 'gvh', 'lip', 'chg', 'aac', 'alm1', 'alm2']
target_column = 'localization_class'

X = df[feature_columns]
y = df[target_column]
print("\n[INFO] Ringkasan struktur data:")
X.info()

print("\n[ANALISIS] Distribusi kelas sebelum penyeimbangan:")
print("Ini menunjukkan adanya ketidakseimbangan (imbalance) yang signifikan.")
class_counts_before = y.value_counts()
print(class_counts_before)
------------------

----- stdout -----

--- LANGKAH 2: Menganalisis dan Mempersiapkan Data ---
------------------

[0;31m---------------------------------------------------------------------------[0m
[0;31mNameError[0m                                 Traceback (most recent call last)
[0;32m/tmp/ipython-input-2320132956.py[0m in [0;36m<cell line: 0>[0;34m()[0m
[1;32m      4[0m [0mtarget_column[0m [0;34m=[0m [0;34m'localization_class'[0m[0;34m[0m[0;34m[0m[0m
[1;32m      5[0m [0;34m[0m[0m
[0;32m----> 6[0;31m [0mX[0m [0;34m=[0m [0mdf[0m[0;34m[[0m[0mfeature_columns[0m[0;34m][0m[0;34m[0m[0;34m[0m[0m
[0m[1;32m      7[0m [0my[0m [0;34m=[0m [0mdf[0m[0;34m[[0m[0mtarget_column[0m[0;34m][0m[0;34m[0m[0;34m[0m[0m
[1;32m      8[0m [0mprint[0m[0;34m([0m[0;34m"\n[INFO] Ringkasan struktur data:"[0m[0;34m)[0m[0;34m[0m[0;34m[0m[0m

[0;31mNameError[0m: name 'df' is not defined

